<?xml version="1.0"?>
<robot name="qbot">

    <link name="base_footprint"/>

    <joint name="base_footprint_joint" type="fixed">
        <parent link="base_link"/>
        <child link="base_footprint"/>
        <origin xyz="0 0 0" rpy="0 0 0"/>
    </joint>

    <link name="base_link">
        <visual>
            <origin xyz="0 0 0" rpy="0 0 0"/>
            <geometry>
                <cylinder length="0.10938" radius="0.178"/>
            </geometry>
            <material name="blue">
                <color rgba="0.0 0.0 0.8 1.0"/>
            </material>
        </visual>
        <collision>
            <origin xyz="0 0 0" rpy="0 0 0"/>
            <geometry>
                <cylinder length="0.10938" radius="0.178"/>
            </geometry>
        </collision>
        <inertial>
            <origin xyz="0 0 0" rpy="0 0 0"/>
            <mass value="2.0"/>
            <inertia ixx="0.0178" ixy="0.0" ixz="0.0" iyy="0.0178" iyz="0.0" izz="0.0316"/>
        </inertial>
    </link>

    <joint name="wheel_left_joint" type="continuous">
        <parent link="base_link"/>
        <child link="wheel_left_link"/>
        <origin xyz="0 0.193 0.025" rpy="-1.5708 0 0"/>
        <axis xyz="0 0 1"/>
    </joint>

    <link name="wheel_left_link">
        <visual>
            <origin xyz="0 0 0" rpy="0 0 0"/>
            <geometry>
                <cylinder length="0.03" radius="0.05"/>
            </geometry>
            <material name="black">
                <color rgba="0.1 0.1 0.1 1.0"/>
            </material>
        </visual>
        <collision>
            <origin xyz="0 0 0" rpy="0 0 0"/>
            <geometry>
                <cylinder length="0.03" radius="0.05"/>
            </geometry>
        </collision>
        <inertial>
            <origin xyz="0 0 0" rpy="0 0 0"/>
            <mass value="0.2"/>
            <inertia ixx="0.00014" ixy="0.0" ixz="0.0" iyy="0.00014" iyz="0.0" izz="0.00025"/>
        </inertial>
    </link>

    <joint name="wheel_right_joint" type="continuous">
        <parent link="base_link"/>
        <child link="wheel_right_link"/>
        <origin xyz="0 -0.193 0.025" rpy="-1.5708 0 0"/>
        <axis xyz="0 0 1"/>
    </joint>

    <link name="wheel_right_link">
        <visual>
            <origin xyz="0 0 0" rpy="0 0 0"/>
            <geometry>
                <cylinder length="0.03" radius="0.05"/>
            </geometry>
            <material name="black"/>
        </visual>
        <collision>
            <origin xyz="0 0 0" rpy="0 0 0"/>
            <geometry>
                <cylinder length="0.03" radius="0.05"/>
            </geometry>
        </collision>
        <inertial>
            <origin xyz="0 0 0" rpy="0 0 0"/>
            <mass value="0.2"/>
            <inertia ixx="0.00014" ixy="0.0" ixz="0.0" iyy="0.00014" iyz="0.0" izz="0.00025"/>
        </inertial>
    </link>

    <joint name="caster_front_joint" type="fixed">
        <parent link="base_link"/>
        <child link="caster_front_link"/>
        <origin xyz="0.115 0 0.007" rpy="-1.5708 0 0"/>
    </joint>

    <link name="caster_front_link">
        <visual>
            <origin xyz="0 0 0" rpy="0 0 0"/>
            <geometry>
                <sphere radius="0.025"/>
            </geometry>
            <material name="gray">
                <color rgba="0.5 0.5 0.5 1.0"/>
            </material>
        </visual>
        <collision>
            <origin xyz="0 0 0" rpy="0 0 0"/>
            <geometry>
                <sphere radius="0.025"/>
            </geometry>
        </collision>
        <inertial>
            <origin xyz="0 0 0" rpy="0 0 0"/>
            <mass value="0.1"/>
            <inertia ixx="0.000025" ixy="0.0" ixz="0.0" iyy="0.000025" iyz="0.0" izz="0.000025"/>
        </inertial>
    </link>

    <joint name="caster_back_joint" type="fixed">
        <parent link="base_link"/>
        <child link="caster_back_link"/>
        <origin xyz="-0.135 0 0.009" rpy="-1.5708 0 0"/>
    </joint>

    <link name="caster_back_link">
        <visual>
            <origin xyz="0 0 0" rpy="0 0 0"/>
            <geometry>
                <sphere radius="0.025"/>
            </geometry>
            <material name="gray"/>
        </visual>
        <collision>
            <origin xyz="0 0 0" rpy="0 0 0"/>
            <geometry>
                <sphere radius="0.025"/>
            </geometry>
        </collision>
        <inertial>
            <origin xyz="0 0 0" rpy="0 0 0"/>
            <mass value="0.1"/>
            <inertia ixx="0.000025" ixy="0.0" ixz="0.0" iyy="0.000025" iyz="0.0" izz="0.000025"/>
        </inertial>
    </link>

    <joint name="sensor_mount_joint" type="fixed">
        <parent link="base_link"/>
        <child link="sensor_mount_link"/>
        <origin xyz="0 0 0.139" rpy="0 0 0"/>
    </joint>

    <link name="sensor_mount_link">
        <visual>
            <origin xyz="0 0 0" rpy="0 0 0"/>
            <geometry>
                <box size="0.08 0.12 0.05"/>
            </geometry>
            <material name="red">
                <color rgba="0.8 0.0 0.0 1.0"/>
            </material>
        </visual>
        <collision>
            <origin xyz="0 0 0" rpy="0 0 0"/>
            <geometry>
                <box size="0.08 0.12 0.05"/>
            </geometry>
        </collision>
        <inertial>
            <origin xyz="0 0 0" rpy="0 0 0"/>
            <mass value="0.1"/>
            <inertia ixx="0.00014" ixy="0.0" ixz="0.0" iyy="0.00007" iyz="0.0" izz="0.00017"/>
        </inertial>
    </link>

    <gazebo reference="caster_front_link">
        <mu1>0.0</mu1>
        <mu2>0.0</mu2>
    </gazebo>
    <gazebo reference="caster_back_link">
        <mu1>0.0</mu1>
        <mu2>0.0</mu2>
    </gazebo>
 
    <ros2_control name="qbot_system" type="system">
        <hardware>
            <plugin>ign_ros2_control/IgnitionSystem</plugin>
        </hardware>
        <joint name="wheel_left_joint">
            <command_interface name="velocity">
                <param name="min">-10</param>
                <param name="max">10</param>
            </command_interface>
            <state_interface name="position"/>
            <state_interface name="velocity"/>
        </joint>
        <joint name="wheel_right_joint">
            <command_interface name="velocity">
                <param name="min">-10</param>
                <param name="max">10</param>
            </command_interface>
            <state_interface name="position"/>
            <state_interface name="velocity"/>
        </joint>
    </ros2_control>
    
    <gazebo>
        <plugin filename="ign_ros2_control-system" name="ign_ros2_control::IgnitionROS2ControlPlugin">
            <parameters>$(find qbot_description)/config/qbot_controller.yaml</parameters>
        </plugin>
    </gazebo>

</robot>